package main
 
type customError struct {
    msg string
}
 
func (e *customError) Error() string {
    return e.msg
}
 
func test() *customError {
     {
         // do something
     }
     return nil
}
 
func main() {
    var err error
    err = test()
    if err != nil {
        println("error")
        return
    }
    println("ok")
}

Ответ: программа выводит error, так как после присвоения переменной err результата функции test, переменная будет иметь тип, но не будет иметь значение. Соответственно при сравнении с nil, они равны не будут.